<mujoco model="MuJoCo Model">
  <compiler angle="radian"/>

  <worldbody>
    <geom size="5 5 0.1" type="plane" rgba="0.9 0.9 0.9 1"/>
    <light pos="0 0 3" dir="0 0 -1"/>
    <body name="torso" pos="0 0 1">
      <joint type="free"/>
      <geom size="0.2" rgba="0 0.5 1 1"/>
      <body name="leg" pos="0 0 -0.2">
        <joint name="knee" pos="0 0 0" axis="0 1 0"/>
        <geom size="0.05 0.25" pos="0 0 -0.25" type="capsule" rgba="1 0 0 1"/>
      </body>
    </body>
  </worldbody>
</mujoco>
